Workbook
Name College: #REF!
Name College: #REF!
Name College: #REF!
Name College: #REF!
Name College: #REF!
Name College: #REF!
Name College: #REF!
Name College: #REF!
Name College: #REF!
Name College: #REF!
Name College: #REF!
Name College: #REF!
Name College: #REF!
Name College: #REF!
Name College: #REF!
Name College: #REF!
Name College: #REF!
Name College: #REF!
Name College: #REF!
Name College: #REF!
Name College: #REF!
Name College: #REF!
Name College: #REF!
Name College: #REF!
Name College: #REF!
Name College: #REF!
Name College: #REF!
Name d: #REF!
Name d: #REF!
Name d: #REF!
Name d: #REF!
Name d: #REF!
Name d: #REF!
Name d: #REF!
Name d: #REF!
Name d: #REF!
Name d: #REF!
Name d: #REF!
Name d: #REF!
Name d: #REF!
Name d: #REF!
Name d: #REF!
Name d: #REF!
Name d: #REF!
Name d: #REF!
Name d: #REF!
Name d: #REF!
Name d: #REF!
Name d: #REF!
Name d: #REF!
Name d: #REF!
Name d: #REF!
Name d: #REF!
Name JR_PAGE_ANCHOR_0_1: #REF!
Name JR_PAGE_ANCHOR_0_1: #REF!
Name JR_PAGE_ANCHOR_0_1: #REF!
Name JR_PAGE_ANCHOR_0_1: #REF!
Name JR_PAGE_ANCHOR_0_1: #REF!
Name JR_PAGE_ANCHOR_0_1: #REF!
Name JR_PAGE_ANCHOR_0_1: #REF!

Sheet 1UniNo
B1: Table | C1: 1. State & Type - Wise Number of Universities
A2: Sl. No. | B2: State | C2: Central University | D2: Central Open University | E2: Institute of National Importance | F2: State Public University | G2: Institute under State Legislature Act | H2: State Open University | I2: State Private University | J2: State Private Open University | K2: Deemed University-Government | L2: Deemed University-Government Aided | M2: Deemed University-Private | N2: Grand Total | P2: Govt. | Q2: Govt. Aided | R2: Private
A3: 1 | B3: 2 | C3: 3 | D3: 4 | E3: 5 | F3: 6 | G3: 7 | H3: 8 | I3: 9 | J3: 10 | K3: 11 | L3: 12 | M3: 13 | N3: 14
A4: 1 | B4: Andhra Pradesh | C4: 2 | D4: 0 | E4: 10 | F4: 23 | G4: 1 | H4: 0 | I4: 5 | J4: 0 | K4: 0 | L4: 0 | M4: 4 | N4: 45
A5: 2 | B5: Arunachal Pradesh | C5: 1 | D5: 0 | E5: 1 | F5: 0 | G5: 0 | H5: 0 | I5: 6 | J5: 1 | K5: 1 | L5: 0 | M5: 0 | N5: 10
A6: 3 | B6: Assam | C6: 2 | D6: 0 | E6: 5 | F6: 13 | G6: 0 | H6: 1 | I6: 6 | J6: 0 | K6: 1 | L6: 0 | M6: 0 | N6: 28
A7: 4 | B7: Bihar | C7: 4 | D7: 0 | E7: 6 | F7: 17 | G7: 1 | H7: 1 | I7: 7 | J7: 0 | K7: 1 | L7: 0 | M7: 0 | N7: 37
A8: 5 | B8: Chandigarh | C8: 0 | D8: 0 | E8: 1 | F8: 1 | G8: 0 | H8: 0 | I8: 0 | J8: 0 | K8: 1 | L8: 0 | M8: 0 | N8: 3
A9: 6 | B9: Chhattisgarh | C9: 1 | D9: 0 | E9: 4 | F9: 14 | G9: 0 | H9: 1 | I9: 12 | J9: 0 | K9: 0 | L9: 0 | M9: 0 | N9: 32
A10: 7 | B10: Delhi | C10: 6 | D10: 1 | E10: 5 | F10: 8 | G10: 0 | H10: 0 | I10: 0 | J10: 0 | K10: 6 | L10: 1 | M10: 1 | N10: 28
A11: 8 | B11: Goa | C11: 0 | D11: 0 | E11: 2 | F11: 1 | G11: 0 | H11: 0 | I11: 0 | J11: 0 | K11: 0 | L11: 0 | M11: 0 | N11: 3
A12: 9 | B12: Gujarat | C12: 1 | D12: 0 | E12: 9 | F12: 25 | G12: 0 | H12: 1 | I12: 44 | J12: 0 | K12: 1 | L12: 1 | M12: 1 | N12: 83
A13: 10 | B13: Haryana | C13: 1 | D13: 0 | E13: 5 | F13: 20 | G13: 0 | H13: 0 | I13: 24 | J13: 0 | K13: 3 | L13: 0 | M13: 3 | N13: 56
A14: 11 | B14: Himachal Pradesh | C14: 1 | D14: 0 | E14: 4 | F14: 7 | G14: 0 | H14: 0 | I14: 17 | J14: 0 | K14: 0 | L14: 0 | M14: 0 | N14: 29
A15: 12 | B15: Jammu and Kashmir | C15: 2 | D15: 0 | E15: 3 | F15: 9 | G15: 1 | H15: 0 | I15: 0 | J15: 0 | K15: 0 | L15: 0 | M15: 0 | N15: 15
... A36: 33 | B36: West Bengal | C36: 1 | D36: 0 | E36: 8 | F36: 29 | G36: 0 | H36: 1 | I36: 11 | J36: 0 | K36: 1 | L36: 0 | M36: 1 | N36: 52
A37: All India | C37: 51 | D37: 1 | E37: 149 | F37: 403 | G37: 5 | H37: 14 | I37: 365 | J37: 1 | K37: 34 | L37: 10 | M37: 80 | N37: 1113 | P37: =I37+J37+M37 -> 446
B38: In UTs of , Andaman & Nicobar Islands, Dadra & Nagar Haveli, Daman & Diu and Lakshadweep, there is no University.
B41: Government | C41: =N37-C42-C43 -> 657
B42: Private | C42: 10
B43: Government Aided | C43: 446

Sheet 1InsResponse
B1: Table 1(a). | C1: Total Number of Institutions Registered and Responded in AISHE 2020-21
A2: Sl. No. | B2: State/UTs | C2: Unversities | F2: Colleges | I2: Standalone Institutions | L2: Total
C3: Registered | D3: Responded | E3: % of Response | F3: Registered | G3: Responded | H3: % of Response | I3: Registered | J3: Responded | K3: % of Response | L3: Registered | M3: Responded | N3: % of Response | O3: DCF NA
A4: 1 | B4: 2 | C4: 3 | D4: 4 | E4: 5 | F4: 6 | G4: 7 | H4: 8 | I4: 9 | J4: 10 | K4: 11 | L4: 12 | M4: 13 | N4: 14
A5: 1 | B5: Andaman and Nicobar Islands | C5: 0 | D5: 0 | F5: 9 | G5: ='8CollegeAct'!D5 -> 9 | H5: 100 | I5: 1 | J5: 1 | K5: 100 | L5: =C5+F5+I5 -> 10 | M5: =D5+G5+J5 -> 10 | N5: 100 | O5: 0
A6: 2 | B6: Andhra Pradesh | C6: 45 | D6: 45 | E6: 100 | F6: 2601 | G6: ='8CollegeAct'!D6 -> 2554 | H6: 98 | I6: 698 | J6: 654 | K6: 94 | L6: =C6+F6+I6 -> 3344 | M6: =D6+G6+J6 -> 3253 | N6: 97 | O6: 2
A7: 3 | B7: Arunachal Pradesh | C7: 10 | D7: 10 | E7: 100 | F7: 42 | G7: ='8CollegeAct'!D7 -> 41 | H7: 100 | I7: 14 | J7: 14 | K7: 100 | L7: =C7+F7+I7 -> 66 | M7: =D7+G7+J7 -> 65 | N7: 100 | O7: 1
A8: 4 | B8: Assam | C8: 28 | D8: 28 | E8: 100 | F8: 595 | G8: ='8CollegeAct'!D8 -> 560 | H8: 94 | I8: 93 | J8: 83 | K8: 89 | L8: =C8+F8+I8 -> 716 | M8: =D8+G8+J8 -> 671 | N8: 94 | O8: 1
A9: 5 | B9: Bihar | C9: 37 | D9: 37 | E9: 100 | F9: 1035 | G9: ='8CollegeAct'!D9 -> 1032 | H9: 100 | I9: 283 | J9: 264 | K9: 93 | L9: =C9+F9+I9 -> 1355 | M9: =D9+G9+J9 -> 1333 | N9: 99 | O9: 3
A10: 6 | B10: Chandigarh | C10: 3 | D10: 3 | E10: 100 | F10: 26 | G10: ='8CollegeAct'!D10 -> 26 | H10: 100 | I10: 10 | J10: 10 | K10: 100 | L10: =C10+F10+I10 -> 39 | M10: =D10+G10+J10 -> 39 | N10: 100 | O10: 0
A11: 7 | B11: Chhattisgarh | C11: 32 | D11: 32 | E11: 100 | F11: 870 | G11: ='8CollegeAct'!D11 -> 849 | H11: 99 | I11: 79 | J11: 70 | K11: 89 | L11: =C11+F11+I11 -> 981 | M11: =D11+G11+J11 -> 951 | N11: 98 | O11: 14
A12: 8 | B12: Delhi | C12: 28 | D12: 27 | E12: 96 | F12: 180 | G12: ='8CollegeAct'!D12 -> 173 | H12: 96 | I12: 97 | J12: 85 | K12: 89 | L12: =C12+F12+I12 -> 305 | M12: =D12+G12+J12 -> 285 | N12: 94 | O12: 0
A13: 9 | B13: Goa | C13: 3 | D13: 3 | E13: 100 | F13: 61 | G13: ='8CollegeAct'!D13 -> 61 | H13: 100 | I13: 17 | J13: 17 | K13: 100 | L13: =C13+F13+I13 -> 81 | M13: =D13+G13+J13 -> 81 | N13: 100 | O13: 0
A14: 10 | B14: Gujarat | C14: 83 | D14: 83 | E14: 100 | F14: 2267 | G14: ='8CollegeAct'!D14 -> 2248 | H14: 100 | I14: 301 | J14: 301 | K14: 100 | L14: =C14+F14+I14 -> 2651 | M14: =D14+G14+J14 -> 2632 | N14: 100 | O14: 22
A15: 11 | B15: Haryana | C15: 56 | D15: 56 | E15: 100 | F15: 1083 | G15: 1081 | H15: 100 | I15: 228 | J15: 221 | K15: 97 | L15: =C15+F15+I15 -> 1367 | M15: =D15+G15+J15 -> 1358 | N15: 99 | O15: 2
A16: 12 | B16: Himachal Pradesh | C16: 29 | D16: 28 | E16: 97 | F16: 348 | G16: ='8CollegeAct'!D16 -> 348 | H16: 100 | I16: 83 | J16: 79 | K16: 95 | L16: =C16+F16+I16 -> 460 | M16: =D16+G16+J16 -> 455 | N16: 99 | O16: 0
A17: 13 | B17: Jammu and Kashmir | C17: 15 | D17: 15 | E17: 100 | F17: 348 | G17: ='8CollegeAct'!D17 -> 342 | H17: 99 | I17: 154 | J17: 134 | K17: 87 | L17: =C17+F17+I17 -> 517 | M17: =D17+G17+J17 -> 491 | N17: 96 | O17: 3
A18: 14 | B18: Jharkhand | C18: 32 | D18: 32 | E18: 100 | F18: 336 | G18: ='8CollegeAct'!D18 -> 336 | H18: 100 | I18: 109 | J18: 96 | K18: 88 | L18: =C18+F18+I18 -> 477 | M18: =D18+G18+J18 -> 464 | N18: 97 | O18: 0
A19: 15 | B19: Karnataka | C19: 72 | D19: 72 | E19: 100 | F19: 4233 | G19: ='8CollegeAct'!D19 -> 4109 | H19: 97 | I19: 1592 | J19: 1230 | K19: 77 | L19: =C19+F19+I19 -> 5897 | M19: =D19+G19+J19 -> 5411 | N19: 92 | O19: 15
A20: 16 | B20: Kerala | C20: 23 | D20: 23 | E20: 100 | F20: 1448 | G20: ='8CollegeAct'!D20 -> 1328 | H20: 92 | I20: 376 | J20: 369 | K20: 98 | L20: =C20+F20+I20 -> 1847 | M20: =D20+G20+J20 -> 1720 | N20: 94 | O20: 10
A21: 17 | B21: Ladakh | C21: 2 | D21: 1 | E21: 50 | F21: 3 | G21: ='8CollegeAct'!D21 -> 3 | H21: 100 | I21: 5 | J21: 3 | K21: 60 | L21: =C21+F21+I21 -> 10 | M21: =D21+G21+J21 -> 7 | N21: 70 | O21: 0
A22: 18 | B22: Lakshadweep* | D22: 0 | F22: 0 | G22: ='8CollegeAct'!D22 -> 0 | I22: 0 | J22: 0 | L22: =C22+F22+I22 -> 0 | M22: =D22+G22+J22 -> 0 | O22: 0
A23: 19 | B23: Madhya Pradesh | C23: 74 | D23: 74 | E23: 100 | F23: 2610 | G23: ='8CollegeAct'!D23 -> 2319 | H23: 90 | I23: 335 | J23: 250 | K23: 75 | L23: =C23+F23+I23 -> 3019 | M23: =D23+G23+J23 -> 2643 | N23: 88 | O23: 21
A24: 20 | B24: Maharashtra | C24: 71 | D24: 71 | E24: 100 | F24: 4532 | G24: ='8CollegeAct'!D24 -> 4531 | H24: 100 | I24: 2153 | J24: 2110 | K24: 98 | L24: =C24+F24+I24 -> 6756 | M24: =D24+G24+J24 -> 6712 | N24: 99 | O24: 2
A25: 21 | B25: Manipur | C25: 9 | D25: 8 | E25: 89 | F25: 105 | G25: ='8CollegeAct'!D25 -> 103 | H25: 98 | I25: 34 | J25: 30 | K25: 88 | L25: =C25+F25+I25 -> 148 | M25: =D25+G25+J25 -> 141 | N25: 95 | O25: 0
A26: 22 | B26: Meghalaya | C26: 11 | D26: 10 | E26: 91 | F26: 75 | G26: ='8CollegeAct'!D26 -> 62 | H26: 84 | I26: 22 | J26: 21 | K26: 95 | L26: =C26+F26+I26 -> 108 | M26: =D26+G26+J26 -> 93 | N26: 87 | O26: 1
A27: 23 | B27: Mizoram | C27: 3 | D27: 3 | E27: 100 | F27: 39 | G27: ='8CollegeAct'!D27 -> 39 | H27: 100 | I27: 19 | J27: 19 | K27: 100 | L27: =C27+F27+I27 -> 61 | M27: =D27+G27+J27 -> 61 | N27: 100 | O27: 0
A28: 24 | B28: Nagaland | C28: 5 | D28: 5 | E28: 100 | F28: 68 | G28: ='8CollegeAct'!D28 -> 67 | H28: 100 | I28: 20 | J28: 20 | K28: 100 | L28: =C28+F28+I28 -> 93 | M28: =D28+G28+J28 -> 92 | N28: 100 | O28: 1
A29: 25 | B29: Odisha | C29: 36 | D29: 36 | E29: 100 | F29: 1206 | G29: ='8CollegeAct'!D29 -> 1195 | H29: 100 | I29: 481 | J29: 481 | K29: 100 | L29: =C29+F29+I29 -> 1723 | M29: =D29+G29+J29 -> 1712 | N29: 100 | O29: 11
A30: 26 | B30: Puducherry | C30: 4 | D30: 4 | E30: 100 | F30: 81 | G30: ='8CollegeAct'!D30 -> 70 | H30: 86 | I30: 12 | J30: 12 | K30: 100 | L30: =C30+F30+I30 -> 97 | M30: =D30+G30+J30 -> 86 | N30: 89 | O30: 0
A31: 27 | B31: Punjab | C31: 34 | D31: 34 | E31: 100 | F31: 1039 | G31: ='8CollegeAct'!D31 -> 1030 | H31: 100 | I31: 362 | J31: 351 | K31: 97 | L31: =C31+F31+I31 -> 1435 | M31: =D31+G31+J31 -> 1415 | N31: 99 | O31: 8
A32: 28 | B32: Rajasthan | C32: 92 | D32: 88 | E32: 96 | F32: 3694 | G32: ='8CollegeAct'!D32 -> 3339 | H32: 91 | I32: 514 | J32: 430 | K32: 84 | L32: =C32+F32+I32 -> 4300 | M32: =D32+G32+J32 -> 3857 | N32: 90 | O32: 20
A33: 29 | B33: Sikkim | C33: 8 | D33: 7 | E33: 88 | F33: 23 | G33: ='8CollegeAct'!D33 -> 19 | H33: 87 | I33: 8 | J33: 8 | K33: 100 | L33: =C33+F33+I33 -> 39 | M33: =D33+G33+J33 -> 34 | N33: 90 | O33: 1
A34: 30 | B34: Tamil Nadu | C34: 59 | D34: 59 | E34: 100 | F34: 2667 | G34: ='8CollegeAct'!D34 -> 2657 | H34: 100 | I34: 895 | J34: 891 | K34: 100 | L34: =C34+F34+I34 -> 3621 | M34: =D34+G34+J34 -> 3607 | N34: 100 | O34: 4
A35: 31 | B35: Telangana | C35: 31 | D35: 30 | E35: 97 | F35: 2062 | G35: ='8CollegeAct'!D35 -> 2025 | H35: 99 | I35: 458 | J35: 448 | K35: 98 | L35: =C35+F35+I35 -> 2551 | M35: =D35+G35+J35 -> 2503 | N35: 98 | O35: 9
A36: 32 | B36: The Dadra and Nagar Haveli and Daman and Diu | D36: 0 | F36: 19 | G36: ='8CollegeAct'!D36 -> 19 | H36: 100 | I36: 1 | J36: 1 | K36: 100 | L36: =C36+F36+I36 -> 20 | M36: =D36+G36+J36 -> 20 | N36: 100 | O36: 0
A37: 33 | B37: Tripura | C37: 5 | D37: 5 | E37: 100 | F37: 54 | G37: ='8CollegeAct'!D37 -> 53 | H37: 98 | I37: 14 | J37: 12 | K37: 86 | L37: =C37+F37+I37 -> 73 | M37: =D37+G37+J37 -> 70 | N37: 96 | O37: 0
A38: 34 | B38: Uttar Pradesh | C38: 84 | D38: 81 | E38: 96 | F38: 8114 | G38: ='8CollegeAct'!D38 -> 7127 | H38: 88 | I38: 1148 | J38: 917 | K38: 80 | L38: =C38+F38+I38 -> 9346 | M38: =D38+G38+J38 -> 8125 | N38: 87 | O38: 17
A39: 35 | B39: Uttarakhand | C39: 37 | D39: 37 | E39: 100 | F39: 477 | G39: ='8CollegeAct'!D39 -> 403 | H39: 85 | I39: 153 | J39: 149 | K39: 97 | L39: =C39+F39+I39 -> 667 | M39: =D39+G39+J39 -> 589 | N39: 88 | O39: 1
A40: 36 | B40: West Bengal | C40: 52 | D40: 52 | E40: 100 | F40: 1446 | G40: ='8CollegeAct'!D40 -> 1442 | H40: 100 | I40: 527 | J40: 526 | K40: 100 | L40: =C40+F40+I40 -> 2025 | M40: =D40+G40+J40 -> 2020 | N40: 100 | O40: 3
...

Sheet 2University-Specialisation
B1: Table 2. | C1: State & Specialisation-wise Number of Universities (Based on Actual Response) | M1: =C1 -> State & Specialisation-wise Number of Universities (Based on Actual Response)
A2: Sl. No. | B2: State/UTs | C2: General | D2: Agriculture | E2: Education | F2: Chartered Accountant | G2: Cultural Studies | H2: Fine Arts | I2: Fisheries | J2: Gandhian / Religious Study | K2: Journalism & Mass Communication | L2: Language | M2: Law | N2: Management | O2: Medical | P2: Oriental Learning | Q2: Rural Development | R2: Sanskrit | S2: Science | T2: Social Science | U2: Sports/Yoga/Physical Education | V2: Technical | W2: Veterinary | X2: Other | Y2: Grand Total
A3: 1 | B3: 2 | C3: 3 | D3: 4 | E3: 5 | F3: 6 | G3: 7 | H3: 8 | I3: 9 | J3: 10 | K3: 11 | L3: 12 | M3: 13 | N3: 14 | O3: 15 | P3: 16 | Q3: 17 | R3: 18 | S3: 19 | T3: 20 | U3: 21 | V3: 22 | W3: 23 | X3: 24 | Y3: 25
A4: 1 | B4: Andhra Pradesh | C4: 19 | D4: 2 | H4: 1 | L4: 1 | M4: 1 | N4: 1 | O4: 3 | R4: 2 | S4: 2 | V4: 12 | W4: 1 | Y4: 45
A5: 2 | B5: Arunachal Pradesh | C5: 7 | O5: 1 | V5: 2 | Y5: 10
A6: 3 | B6: Assam | C6: 16 | D6: 1 | M6: 1 | O6: 2 | R6: 1 | V6: 7 | Y6: 28
A7: 4 | B7: Bihar | C7: 25 | D7: 2 | N7: 1 | O7: 3 | P7: 1 | R7: 1 | V7: 3 | W7: 1 | Y7: 37
A8: 5 | B8: Chandigarh | C8: 1 | O8: 1 | V8: 1 | Y8: 3
A9: 6 | B9: Chhattisgarh | C9: 21 | E9: 1 | K9: 1 | M9: 1 | N9: 2 | O9: 2 | V9: 4 | Y9: 32
A10: 7 | B10: Delhi | C10: 9 | D10: 1 | E10: 1 | M10: 2 | O10: 3 | R10: 2 | V10: 8 | X10: 1 | Y10: 27
A11: 8 | B11: Goa | C11: 1 | V11: 2 | Y11: 3
A12: 9 | B12: Gujarat | C12: 50 | D12: 4 | E12: 1 | M12: 1 | N12: 2 | O12: 4 | R12: 1 | S12: 2 | U12: 2 | V12: 15 | X12: 1 | Y12: 83
A13: 10 | B13: Haryana | C13: 34 | D13: 3 | M13: 1 | N13: 1 | O13: 3 | R13: 1 | S13: 3 | T13: 1 | V13: 8 | W13: 1 | Y13: 56
A14: 11 | B14: Himachal Pradesh | C14: 16 | D14: 2 | F14: 1 | M14: 1 | N14: 1 | V14: 7 | Y14: 28
A15: 12 | B15: Jammu and Kashmir | C15: 8 | D15: 2 | N15: 1 | O15: 1 | S15: 1 | V15: 2 | Y15: 15
A16: 13 | B16: Jharkhand | C16: 20 | D16: 1 | F16: 1 | M16: 1 | N16: 1 | O16: 1 | V16: 6 | X16: 1 | Y16: 32
A17: 14 | B17: Karnataka | C17: 41 | D17: 5 | H17: 1 | M17: 2 | N17: 1 | O17: 5 | Q17: 1 | R17: 1 | S17: 4 | T17: 2 | U17: 1 | V17: 7 | W17: 1 | Y17: 72
A18: 15 | B18: Kerala | C18: 6 | D18: 1 | I18: 1 | L18: 1 | M18: 1 | N18: 1 | O18: 2 | R18: 1 | S18: 2 | V18: 5 | W18: 1 | X18: 1 | Y18: 23
A19: 16 | B19: Ladakh | P19: 1 | Y19: 1
A20: 17 | B20: Madhya Pradesh | C20: 47 | D20: 2 | H20: 1 | J20: 1 | K20: 1 | L20: 1 | M20: 2 | N20: 1 | O20: 3 | R20: 2 | S20: 3 | U20: 1 | V20: 9 | Y20: 74
A21: 18 | B21: Maharashtra | C21: 35 | D21: 4 | H21: 1 | I21: 1 | L21: 1 | M21: 3 | N21: 2 | O21: 7 | R21: 1 | S21: 4 | T21: 3 | V21: 8 | W21: 1 | Y21: 71
A22: 19 | B22: Manipur | C22: 2 | D22: 1 | G22: 1 | U22: 1 | V22: 3 | Y22: 8
A23: 20 | B23: Meghalaya | C23: 5 | F23: 1 | N23: 1 | S23: 1 | V23: 2 | Y23: 10
A24: 21 | B24: Mizoram | C24: 1 | F24: 1 | V24: 1 | Y24: 3
A25: 22 | B25: Nagaland | C25: 3 | F25: 1 | V25: 1 | Y25: 5
A26: 23 | B26: Odisha | C26: 19 | D26: 1 | G26: 1 | M26: 1 | N26: 1 | O26: 2 | R26: 1 | S26: 1 | T26: 1 | V26: 8 | Y26: 36
A27: 24 | B27: Puducherry | C27: 2 | O27: 1 | V27: 1 | Y27: 4
A28: 25 | B28: Punjab | C28: 18 | D28: 1 | M28: 1 | N28: 1 | O28: 4 | S28: 1 | U28: 1 | V28: 6 | W28: 1 | Y28: 34
A29: 26 | B29: Rajasthan | C29: 56 | D29: 5 | K29: 1 | M29: 2 | N29: 1 | O29: 7 | R29: 2 | S29: 1 | U29: 1 | V29: 11 | W29: 1 | Y29: 88
A30: 27 | B30: Sikkim | C30: 5 | F30: 1 | V30: 1 | Y30: 7
A31: 28 | B31: Tamil Nadu | C31: 25 | D31: 1 | H31: 1 | I31: 1 | L31: 1 | M31: 2 | N31: 1 | O31: 3 | Q31: 1 | S31: 2 | U31: 3 | V31: 17 | W31: 1 | Y31: 59
A32: 29 | B32: Telangana | C32: 15 | D32: 2 | H32: 1 | L32: 1 | M32: 1 | O32: 3 | P32: 1 | V32: 5 | W32: 1 | Y32: 30
A33: 30 | B33: Tripura | C33: 2 | F33: 1 | V33: 2 | Y33: 5
A34: 31 | B34: Uttar Pradesh | C34: 48 | D34: 5 | E34: 1 | J34: 1 | L34: 1 | M34: 1 | N34: 1 | O34: 5 | R34: 1 | V34: 14 | W34: 2 | X34: 1 | Y34: 81
A35: 32 | B35: Uttarakhand | C35: 24 | D35: 3 | N35: 1 | O35: 3 | R35: 2 | V35: 4 | Y35: 37
A36: 33 | B36: West Bengal | C36: 34 | D36: 2 | E36: 1 | I36: 1 | L36: 1 | M36: 1 | N36: 1 | O36: 2 | S36: 3 | V36: 6 | Y36: 52
A37: All India | C37: 615 | D37: 51 | E37: 5 | F37: 7 | G37: 2 | H37: 6 | I37: 4 | J37: 2 | K37: 3 | L37: 8 | M37: 26 | N37: 23 | O37: 71 | P37: 3 | Q37: 2 | R37: 19 | S37: 30 | T37: 7 | U37: 10 | V37: 188 | W37: 12 | X37: 5 | Y37: 1099

Sheet 3Collegerange
A1: Table 3. State-wise Distribution of Districts in Different Ranges of number of Colleges
A2: State | B2: Number of College
B3: Less than 10 | C3: 10-19 | D3: 20-49 | E3: 50-99 | F3: 100-199 | G3: 200-299 | H3: 300-399 | I3: 400-499 | J3: 500-999 | K3: More than 1000
A4: 1 | B4: 2 | C4: 3 | D4: 4 | E4: 5 | F4: 6 | G4: 7 | H4: 8 | I4: 9 | J4: 10 | K4: 11
A5: Andaman and Nicobar Islands | B5: 3 | C5: 0 | D5: 0 | E5: 0 | F5: 0 | G5: 0 | H5: 0 | I5: 0 | J5: 0 | K5: 0 | L5: 3
A6: Andhra Pradesh | B6: 0 | C6: 0 | D6: 0 | E6: 0 | F6: 7 | G6: 6 | H6: 0 | I6: 0 | J6: 0 | K6: 0 | L6: 13
A7: Arunachal Pradesh | B7: 15 | C7: 1 | D7: 0 | E7: 0 | F7: 0 | G7: 0 | H7: 0 | I7: 0 | J7: 0 | K7: 0 | L7: 16
A8: Assam | B8: 7 | C8: 13 | D8: 10 | E8: 1 | F8: 0 | G8: 0 | H8: 0 | I8: 0 | J8: 0 | K8: 0 | L8: 31
A9: Bihar | B9: 6 | C9: 12 | D9: 15 | E9: 4 | F9: 1 | G9: 0 | H9: 0 | I9: 0 | J9: 0 | K9: 0 | L9: 38
A10: Chandigarh | B10: 0 | C10: 0 | D10: 1 | E10: 0 | F10: 0 | G10: 0 | H10: 0 | I10: 0 | J10: 0 | K10: 0 | L10: 1
A11: Chhattisgarh | B11: 7 | C11: 6 | D11: 9 | E11: 2 | F11: 3 | G11: 0 | H11: 0 | I11: 0 | J11: 0 | K11: 0 | L11: 27
A12: Delhi | B12: 2 | C12: 4 | D12: 4 | E12: 0 | F12: 0 | G12: 0 | H12: 0 | I12: 0 | J12: 0 | K12: 0 | L12: 10
A13: Goa | B13: 0 | C13: 0 | D13: 2 | E13: 0 | F13: 0 | G13: 0 | H13: 0 | I13: 0 | J13: 0 | K13: 0 | L13: 2
A14: Gujarat | B14: 1 | C14: 4 | D14: 12 | E14: 8 | F14: 7 | G14: 1 | H14: 0 | I14: 0 | J14: 0 | K14: 0 | L14: 33
A15: Haryana | B15: 1 | C15: 1 | D15: 11 | E15: 9 | F15: 0 | G15: 0 | H15: 0 | I15: 0 | J15: 0 | K15: 0 | L15: 22
A16: Himachal Pradesh | B16: 2 | C16: 3 | D16: 5 | E16: 2 | F16: 0 | G16: 0 | H16: 0 | I16: 0 | J16: 0 | K16: 0 | L16: 12
... A41: All India | B41: 141 | C41: 93 | D41: 187 | E41: 144 | F41: 98 | G41: 29 | H41: 6 | I41: 2 | J41: 1 | K41: 1 | L41: 702

Sheet 4CollegeIndicator
A1: Table 4. Number of College per Lakh Population(18-23 YEARS), Average Enrolment per College
A2: Sl. No. | B2: States/UTs | C2: No. of College | D2: No. of College per lakh population | E2: Average Enrolment
E3: All Colleges | F3: Government College | G3: Private (Un-Aided) | H3: Private (Aided)
A4: 1 | B4: 2 | C4: 3 | D4: 4 | E4: 5 | F4: 6 | G4: 7 | H4: 8
A5: 1 | B5: Andaman and Nicobar Islands | C5: 9 | D5: 17.319016 | E5: 845.33333 | F5: ='5ManagementCollegeNo'!K5/'5ManagementCollegeNo'!F5 -> 845.33333
A6: 2 | B6: Andhra Pradesh | C6: 2601 | D6: 48.758395 | E6: 540.55479 | F6: ='5ManagementCollegeNo'!K6/'5ManagementCollegeNo'!F6 -> 603.50333 | G6: ='5ManagementCollegeNo'!H6/'5ManagementCollegeNo'!C6 -> 519.44524 | H6: ='5ManagementCollegeNo'!I6/'5ManagementCollegeNo'!D6 -> 851.36196
A7: 3 | B7: Arunachal Pradesh | C7: 42 | D7: 26.809138 | E7: 547.11905 | F7: ='5ManagementCollegeNo'!K7/'5ManagementCollegeNo'!F7 -> 727.08696 | G7: ='5ManagementCollegeNo'!H7/'5ManagementCollegeNo'!C7 -> 358.14286 | H7: ='5ManagementCollegeNo'!I7/'5ManagementCollegeNo'!D7 -> 310.5
A8: 4 | B8: Assam | C8: 595 | D8: 15.762362 | E8: 795.42857 | F8: ='5ManagementCollegeNo'!K8/'5ManagementCollegeNo'!F8 -> 980.16593 | G8: ='5ManagementCollegeNo'!H8/'5ManagementCollegeNo'!C8 -> 302.3494 | H8: ='5ManagementCollegeNo'!I8/'5ManagementCollegeNo'!D8 -> 206
A9: 5 | B9: Bihar | C9: 1035 | D9: 8.4588457 | E9: 1880.63 | F9: ='5ManagementCollegeNo'!K9/'5ManagementCollegeNo'!F9 -> 2804.745 | G9: ='5ManagementCollegeNo'!H9/'5ManagementCollegeNo'!C9 -> 439.22492 | H9: ='5ManagementCollegeNo'!I9/'5ManagementCollegeNo'!D9 -> 1730.1329
A10: 6 | B10: Chandigarh | C10: 26 | D10: 12.153679 | E10: 1890.2308 | F10: ='5ManagementCollegeNo'!K10/'5ManagementCollegeNo'!F10 -> 1312.8667 | G10: ='5ManagementCollegeNo'!H10/'5ManagementCollegeNo'!C10 -> 129.75 | H10: ='5ManagementCollegeNo'!I10/'5ManagementCollegeNo'!D10 -> 4133.4286
A11: 7 | B11: Chhattisgarh | C11: 870 | D11: 27.264548 | E11: 545.62644 | F11: ='5ManagementCollegeNo'!K11/'5ManagementCollegeNo'!F11 -> 793.04304 | G11: ='5ManagementCollegeNo'!H11/'5ManagementCollegeNo'!C11 -> 326.81522 | H11: ='5ManagementCollegeNo'!I11/'5ManagementCollegeNo'!D11 -> 478.77907
A12: 8 | B12: Delhi | C12: 180 | D12: 7.5316581 | E12: 1566.5722 | F12: ='5ManagementCollegeNo'!K12/'5ManagementCollegeNo'!F12 -> 2047.3265 | G12: ='5ManagementCollegeNo'!H12/'5ManagementCollegeNo'!C12 -> 959.64062 | H12: ='5ManagementCollegeNo'!I12/'5ManagementCollegeNo'!D12 -> 1811.6364
A13: 9 | B13: Goa | C13: 61 | D13: 32.05583 | E13: 684.01639 | F13: ='5ManagementCollegeNo'!K13/'5ManagementCollegeNo'!F13 -> 684.47619 | G13: ='5ManagementCollegeNo'!H13/'5ManagementCollegeNo'!C13 -> 362.85714 | H13: ='5ManagementCollegeNo'!I13/'5ManagementCollegeNo'!D13 -> 856.57692
A14: 10 | B14: Gujarat | C14: 2267 | D14: 31.228992 | E14: 526.00485 | F14: ='5ManagementCollegeNo'!K14/'5ManagementCollegeNo'!F14 -> 724.26055 | G14: ='5ManagementCollegeNo'!H14/'5ManagementCollegeNo'!C14 -> 343.09701 | H14: ='5ManagementCollegeNo'!I14/'5ManagementCollegeNo'!D14 -> 907.57384
A15: 11 | B15: Haryana | C15: 1083 | D15: 34.050929 | E15: 584.28532 | F15: ='5ManagementCollegeNo'!K15/'5ManagementCollegeNo'!F15 -> 987.10465 | G15: ='5ManagementCollegeNo'!H15/'5ManagementCollegeNo'!C15 -> 316.47591 | H15: ='5ManagementCollegeNo'!I15/'5ManagementCollegeNo'!D15 -> 1169
A16: 12 | B16: Himachal Pradesh | C16: 348 | D16: 49.725723 | E16: 510.2069 | F16: ='5ManagementCollegeNo'!K16/'5ManagementCollegeNo'!F16 -> 823.09146 | G16: ='5ManagementCollegeNo'!H16/'5ManagementCollegeNo'!C16 -> 189.25731 | H16: ='5ManagementCollegeNo'!I16/'5ManagementCollegeNo'!D16 -> 784.76923
A17: 13 | B17: Jammu and Kashmir | C17: 348 | D17: 29.009549 | E17: 593.72414 | F17: ='5ManagementCollegeNo'!K17/'5ManagementCollegeNo'!F17 -> 952.27807 | G17: ='5ManagementCollegeNo'!H17/'5ManagementCollegeNo'!C17 -> 182.75573 | H17: ='5ManagementCollegeNo'!I17/'5ManagementCollegeNo'!D17 -> 191.625
... A20: 16 | B20: Kerala | C20: 1448 | D20: 49.860044 | E20: 530.83149 | F20: ='5ManagementCollegeNo'!K20/'5ManagementCollegeNo'!F20 -> 510.38971 | G20: ='5ManagementCollegeNo'!H20/'5ManagementCollegeNo'!C20 -> 422.01925 | H20: ='5ManagementCollegeNo'!I20/'5ManagementCollegeNo'!D20 -> 1240.5333
A21: 17 | B21: Ladakh | C21: 3 | D21: 8.3363437 | E21: 777.33333 | F21: ='5ManagementCollegeNo'!K21/'5ManagementCollegeNo'!F21 -> 777.33333
A22: 18 | B22: Lakshadweep | C22: 0 | D22: 0
A23: 19 | B23: Madhya Pradesh | C23: 2610 | D23: 28.751013 | E23: 665.77969 | F23: ='5ManagementCollegeNo'!K22/'5ManagementCollegeNo'!F22 -> 1391.7047 | G23: ='5ManagementCollegeNo'!H22/'5ManagementCollegeNo'!C22 -> 420.93997 | H23: ='5ManagementCollegeNo'!I22/'5ManagementCollegeNo'!D22 -> 569.41085
A24: 20 | B24: Maharashtra | C24: 4532 | D24: 34.456327 | E24: 671.5214 | F24: ='5ManagementCollegeNo'!K23/'5ManagementCollegeNo'!F23 -> 570.1985 | G24: ='5ManagementCollegeNo'!H23/'5ManagementCollegeNo'!C23 -> 436.22152 | H24: ='5ManagementCollegeNo'!I23/'5ManagementCollegeNo'!D23 -> 1292.7375
A25: 21 | B25: Manipur | C25: 105 | D25: 32.537356 | E25: 1089.5905 | F25: ='5ManagementCollegeNo'!K24/'5ManagementCollegeNo'!F24 -> 1551.8644 | G25: ='5ManagementCollegeNo'!H24/'5ManagementCollegeNo'!C24 -> 258.78571 | H25: ='5ManagementCollegeNo'!I24/'5ManagementCollegeNo'!D24 -> 975.0625
A26: 22 | B26: Meghalaya | C26: 75 | D26: 22.528476 | E26: 817.02667 | F26: ='5ManagementCollegeNo'!K25/'5ManagementCollegeNo'!F25 -> 1279.0741 | G26: ='5ManagementCollegeNo'!H25/'5ManagementCollegeNo'!C25 -> 502.05882 | H26: ='5ManagementCollegeNo'!I25/'5ManagementCollegeNo'!D25 -> 1011.5
A27: 23 | B27: Mizoram | C27: 39 | D27: 30.897942 | E27: 650.46154 | F27: ='5ManagementCollegeNo'!K26/'5ManagementCollegeNo'!F26 -> 778.41935 | G27: ='5ManagementCollegeNo'!H26/'5ManagementCollegeNo'!C26 -> 172.85714 | H27: ='5ManagementCollegeNo'!I26/'5ManagementCollegeNo'!D26 -> 27
A28: 24 | B28: Nagaland | C28: 68 | D28: 28.410515 | E28: 489.64706 | F28: ='5ManagementCollegeNo'!K27/'5ManagementCollegeNo'!F27 -> 554.05 | G28: ='5ManagementCollegeNo'!H27/'5ManagementCollegeNo'!C27 -> 311.91667 | H28: ='5ManagementCollegeNo'!I27/'5ManagementCollegeNo'!D27 -> 527.77143
A29: 25 | B29: Odisha | C29: 1206 | D29: 26.372254 | E29: 573.31343 | F29: ='5ManagementCollegeNo'!K28/'5ManagementCollegeNo'!F28 -> 689.30458 | G29: ='5ManagementCollegeNo'!H28/'5ManagementCollegeNo'!C28 -> 397.07592 | H29: ='5ManagementCollegeNo'!I28/'5ManagementCollegeNo'!D28 -> 642.5362
A30: 26 | B30: Puducherry | C30: 81 | D30: 45.066097 | E30: 610.65432 | F30: ='5ManagementCollegeNo'!K29/'5ManagementCollegeNo'!F29 -> 1022.64 | G30: ='5ManagementCollegeNo'!H29/'5ManagementCollegeNo'!C29 -> 541.20455 | H30: ='5ManagementCollegeNo'!I29/'5ManagementCollegeNo'!D29 -> 84
A31: 27 | B31: Punjab | C31: 1039 | D31: 34.213094 | E31: 484.42926 | F31: ='5ManagementCollegeNo'!K30/'5ManagementCollegeNo'!F30 -> 722.56281 | G31: ='5ManagementCollegeNo'!H30/'5ManagementCollegeNo'!C30 -> 310.56615 | H31: ='5ManagementCollegeNo'!I30/'5ManagementCollegeNo'!D30 -> 871.07182
A32: 28 | B32: Rajasthan | C32: 3694 | D32: 39.84962 | E32: 466.77152 | F32: ='5ManagementCollegeNo'!K31/'5ManagementCollegeNo'!F31 -> 986.83795 | G32: ='5ManagementCollegeNo'!H31/'5ManagementCollegeNo'!C31 -> 387.44411 | H32: ='5ManagementCollegeNo'!I31/'5ManagementCollegeNo'!D31 -> 379.17045
A33: 29 | B33: Sikkim | C33: 23 | D33: 30.247636 | E33: 577.86957 | F33: ='5ManagementCollegeNo'!K32/'5ManagementCollegeNo'!F32 -> 811.13333 | G33: ='5ManagementCollegeNo'!H32/'5ManagementCollegeNo'!C32 -> 281
A34: 30 | B34: Tamil Nadu | C34: 2667 | D34: 39.549993 | E34: 838.15598 | F34: ='5ManagementCollegeNo'!K33/'5ManagementCollegeNo'!F33 -> 1250.3978 | G34: ='5ManagementCollegeNo'!H33/'5ManagementCollegeNo'!C33 -> 633.57129 | H34: ='5ManagementCollegeNo'!I33/'5ManagementCollegeNo'!D33 -> 1850.566
A35: 31 | B35: Telangana | C35: 2062 | D35: 53.372691 | E35: 555.60281 | F35: ='5ManagementCollegeNo'!K34/'5ManagementCollegeNo'!F34 -> 684.66429 | G35: ='5ManagementCollegeNo'!H34/'5ManagementCollegeNo'!C34 -> 539.7876 | H35: ='5ManagementCollegeNo'!I34/'5ManagementCollegeNo'!D34 -> 643.38793
A36: 32 | B36: The Dadra and Nagar Haveli and Daman and Diu | C36: 19 | D36: 13.798112 | E36: 589 | F36: ='5ManagementCollegeNo'!K35/'5ManagementCollegeNo'!F35 -> 713.2 | G36: ='5ManagementCollegeNo'!H35/'5ManagementCollegeNo'!C35 -> 507.375
A37: 33 | B37: Tripura | C37: 54 | D37: 12.735849 | E37: 1197.5 | F37: ='5ManagementCollegeNo'!K36/'5ManagementCollegeNo'!F36 -> 1358.6279 | G37: ='5ManagementCollegeNo'!H36/'5ManagementCollegeNo'!C36 -> 542.83333 | H37: ='5ManagementCollegeNo'!I36/'5ManagementCollegeNo'!D36 -> 746.75
A38: 34 | B38: Uttar Pradesh | C38: 8114 | D38: 31.840085 | E38: 613.86653 | F38: ='5ManagementCollegeNo'!K37/'5ManagementCollegeNo'!F37 -> 720.18227 | G38: ='5ManagementCollegeNo'!H37/'5ManagementCollegeNo'!C37 -> 620.85422 | H38: ='5ManagementCollegeNo'!I37/'5ManagementCollegeNo'!D37 -> 1309.8841
A39: 35 | B39: Uttarakhand | C39: 477 | D39: 40.387141 | E39: 545.55136 | F39: ='5ManagementCollegeNo'!K38/'5ManagementCollegeNo'!F38 -> 889.18471 | G39: ='5ManagementCollegeNo'!H38/'5ManagementCollegeNo'!C38 -> 410.82741 | H39: ='5ManagementCollegeNo'!I38/'5ManagementCollegeNo'!D38 -> 810.06122
A40: 36 | B40: West Bengal | C40: 1446 | D40: 13.373941 | E40: 1161.2918 | F40: ='5ManagementCollegeNo'!K39/'5ManagementCollegeNo'!F39 -> 2052.2561 | G40: ='5ManagementCollegeNo'!H39/'5ManagementCollegeNo'!C39 -> 401.68925 | H40: ='5ManagementCollegeNo'!I39/'5ManagementCollegeNo'!D39 -> 1464.0996
A41: All India | C41: 43796 | D41: 30.71676 | E41: 646.44166 | F41: ='5ManagementCollegeNo'!K40/'5ManagementCollegeNo'!F40 -> 1097.1615 | G41: ='5ManagementCollegeNo'!H40/'5ManagementCollegeNo'!C40 -> 464.67414 | H41: ='5ManagementCollegeNo'!I40/'5ManagementCollegeNo'!D40 -> 1056.7702
D42: 62.49844
...

Sheet 4aCollegeSpec
A1: Table 4(a). | C1: Specialisation-wise number of Colleges (Based on Actual Response) | N1: Table 4(a). Specialisation-wise number of Colleges (Based on Actual Response) | X1: Table 4(a). Specialisation-wise number of Colleges (Based on Actual Response)
A2: Sl. No. | B2: State/UTs | C2: General | D2: Agriculture | E2: Architecture | F2: Arts | G2: Commerce | H2: Computer Application | I2: Culture | J2: Education/Teacher Education | K2: Engineering & Technology | L2: Fine Arts | M2: Fisheries | N2: Home Science | O2: Hotel & Tourism Management | P2: Journalism & Mass Communication | Q2: Law | R2: Management | S2: Medical-Allopathy | T2: Medical-Ayurveda | U2: Medical-Dental | V2: Medical-Homeopathy | W2: Medical-Others | X2: Nursing | Y2: Oriental Learning | Z2: Others | AA2: Para Medical | AB2: Paramedical | AC2: Pharmacy | AD2: Physiotherapy | AE2: Sanskrit | AF2: Science | AG2: Social Work | AH2: Sports/Yoga/Physical Education | AI2: Veterinary | AJ2: Grand Total
A3: 1 | B3: 2 | C3: 3 | D3: 4 | E3: 5 | F3: 6 | G3: 7 | H3: 8 | I3: 9 | J3: 10 | K3: 11 | L3: 12 | M3: 13 | N3: 14 | O3: 15 | P3: 16 | Q3: 17 | R3: 18 | S3: 19 | T3: 20 | U3: 21 | V3: 22 | W3: 23 | X3: 24 | Y3: 25 | Z3: 26 | AA3: 27 | AB3: 28 | AC3: 29 | AD3: 30 | AE3: 31 | AF3: 32 | AG3: 33 | AH3: 34 | AI3: 35 | AJ3: 36
A4: 1 | B4: Andaman and Nicobar Islands | C4: 3 | D4: 0 | E4: 0 | F4: 0 | G4: 0 | H4: 0 | I4: 0 | J4: 1 | K4: 0 | L4: 0 | M4: 0 | N4: 0 | O4: 0 | P4: 0 | Q4: 1 | R4: 0 | S4: 0 | T4: 0 | U4: 0 | V4: 0 | W4: 0 | X4: 3 | Y4: 0 | Z4: 0 | AA4: 0 | AB4: 0 | AC4: 0 | AD4: 0 | AE4: 0 | AF4: 1 | AG4: 0 | AH4: 0 | AI4: 0 | AJ4: 9 | AK4: 9 | AL4: =AJ4-AK4 -> 0
A5: 2 | B5: Andhra Pradesh | C5: 1819 | D5: 27 | E5: 4 | F5: 6 | G5: 4 | H5: 10 | I5: 0 | J5: 84 | K5: 255 | L5: 0 | M5: 1 | N5: 1 | O5: 7 | P5: 0 | Q5: 16 | R5: 36 | S5: 15 | T5: 2 | U5: 11 | V5: 2 | W5: 16 | X5: 95 | Y5: 2 | Z5: 18 | AA5: 6 | AB5: 1 | AC5: 77 | AD5: 17 | AE5: 5 | AF5: 5 | AG5: 0 | AH5: 9 | AI5: 3 | AJ5: 2554 | AK5: 2554 | AL5: =AJ5-AK5 -> 0
A6: 3 | B6: Arunachal Pradesh | C6: 28 | D6: 1 | E6: 0 | F6: 0 | G6: 0 | H6: 0 | I6: 0 | J6: 7 | K6: 0 | L6: 0 | M6: 0 | N6: 0 | O6: 0 | P6: 0 | Q6: 1 | R6: 0 | S6: 1 | T6: 0 | U6: 0 | V6: 1 | W6: 0 | X6: 2 | Y6: 0 | Z6: 0 | AA6: 0 | AB6: 0 | AC6: 0 | AD6: 0 | AE6: 0 | AF6: 0 | AG6: 0 | AH6: 0 | AI6: 0 | AJ6: 41 | AK6: 41 | AL6: =AJ6-AK6 -> 0
A7: 4 | B7: Assam | C7: 249 | D7: 3 | E7: 1 | F7: 24 | G7: 8 | H7: 0 | I7: 0 | J7: 44 | K7: 154 | L7: 0 | M7: 1 | N7: 0 | O7: 0 | P7: 0 | Q7: 18 | R7: 3 | S7: 2 | T7: 1 | U7: 0 | V7: 1 | W7: 1 | X7: 8 | Y7: 0 | Z7: 4 | AA7: 6 | AB7: 0 | AC7: 14 | AD7: 1 | AE7: 1 | AF7: 3 | AG7: 0 | AH7: 0 | AI7: 13 | AJ7: 560 | AK7: 560 | AL7: =AJ7-AK7 -> 0
A8: 5 | B8: Bihar | C8: 538 | D8: 1 | E8: 0 | F8: 3 | G8: 1 | H8: 10 | I8: 0 | J8: 198 | K8: 126 | L8: 1 | M8: 0 | N8: 0 | O8: 1 | P8: 0 | Q8: 21 | R8: 6 | S8: 9 | T8: 3 | U8: 1 | V8: 6 | W8: 10 | X8: 28 | Y8: 0 | Z8: 7 | AA8: 3 | AB8: 1 | AC8: 16 | AD8: 3 | AE8: 37 | AF8: 0 | AG8: 1 | AH8: 0 | AI8: 1 | AJ8: 1032 | AK8: 1032 | AL8: =AJ8-AK8 -> 0
A9: 6 | B9: Chandigarh | C9: 9 | D9: 0 | E9: 1 | F9: 0 | G9: 1 | H9: 0 | I9: 0 | J9: 5 | K9: 2 | L9: 1 | M9: 0 | N9: 1 | O9: 0 | P9: 0 | Q9: 0 | R9: 1 | S9: 0 | T9: 1 | U9: 0 | V9: 1 | W9: 1 | X9: 0 | Y9: 0 | Z9: 0 | AA9: 0 | AB9: 0 | AC9: 0 | AD9: 0 | AE9: 0 | AF9: 0 | AG9: 0 | AH9: 1 | AI9: 1 | AJ9: 26 | AK9: 26 | AL9: =AJ9-AK9 -> 0
A10: 7 | B10: Chhattisgarh | C10: 454 | D10: 23 | E10: 1 | F10: 5 | G10: 2 | H10: 9 | I10: 0 | J10: 50 | K10: 57 | L10: 3 | M10: 1 | N10: 0 | O10: 0 | P10: 1 | Q10: 17 | R10: 1 | S10: 4 | T10: 5 | U10: 6 | V10: 3 | W10: 4 | X10: 91 | Y10: 0 | Z10: 3 | AA10: 6 | AB10: 0 | AC10: 29 | AD10: 2 | AE10: 56 | AF10: 7 | AG10: 0 | AH10: 3 | AI10: 6 | AJ10: 849 | AK10: 849 | AL10: =AJ10-AK10 -> 0
A11: 8 | B11: Delhi | C11: 76 | D11: 0 | E11: 2 | F11: 1 | G11: 0 | H11: 3 | I11: 0 | J11: 19 | K11: 15 | L11: 1 | M11: 0 | N11: 1 | O11: 1 | P11: 0 | Q11: 1 | R11: 11 | S11: 6 | T11: 2 | U11: 2 | V11: 2 | W11: 4 | X11: 9 | Y11: 0 | Z11: 5 | AA11: 1 | AB11: 0 | AC11: 11 | AD11: 0 | AE11: 0 | AF11: 0 | AG11: 0 | AH11: 0 | AI11: 0 | AJ11: 173 | AK11: 173 | AL11: =AJ11-AK11 -> 0
A12: 9 | B12: Goa | C12: 28 | D12: 1 | E12: 1 | F12: 0 | G12: 1 | H12: 0 | I12: 0 | J12: 4 | K12: 7 | L12: 2 | M12: 0 | N12: 1 | O12: 2 | P12: 0 | Q12: 2 | R12: 0 | S12: 2 | T12: 1 | U12: 1 | V12: 1 | W12: 0 | X12: 2 | Y12: 0 | Z12: 3 | AA12: 0 | AB12: 0 | AC12: 2 | AD12: 0 | AE12: 0 | AF12: 0 | AG12: 0 | AH12: 0 | AI12: 0 | AJ12: 61 | AK12: 61 | AL12: =AJ12-AK12 -> 0
A13: 10 | B13: Gujarat | C13: 729 | D13: 20 | E13: 9 | F13: 63 | G13: 78 | H13: 76 | I13: 0 | J13: 275 | K13: 234 | L13: 2 | M13: 2 | N13: 2 | O13: 5 | P13: 0 | Q13: 52 | R13: 57 | S13: 16 | T13: 14 | U13: 7 | V13: 21 | W13: 127 | X13: 165 | Y13: 0 | Z13: 25 | AA13: 12 | AB13: 3 | AC13: 56 | AD13: 48 | AE13: 41 | AF13: 95 | AG13: 6 | AH13: 3 | AI13: 5 | AJ13: 2248 | AK13: 2248 | AL13: =AJ13-AK13 -> 0
A14: 11 | B14: Haryana | C14: 554 | D14: 4 | E14: 5 | F14: 4 | G14: 0 | H14: 4 | I14: 0 | J14: 269 | K14: 72 | L14: 0 | M14: 1 | N14: 0 | O14: 1 | P14: 0 | Q14: 22 | R14: 19 | S14: 5 | T14: 6 | U14: 7 | V14: 1 | W14: 7 | X14: 33 | Y14: 0 | Z14: 7 | AA14: 1 | AB14: 0 | AC14: 38 | AD14: 5 | AE14: 3 | AF14: 1 | AG14: 0 | AH14: 0 | AI14: 12 | AJ14: 1081 | AK14: 1081 | AL14: =AJ14-AK14 -> 0
A15: 12 | B15: Himachal Pradesh | C15: 197 | D15: 0 | E15: 0 | F15: 2 | G15: 0 | H15: 2 | I15: 0 | J15: 41 | K15: 20 | L15: 1 | M15: 0 | N15: 0 | O15: 4 | P15: 0 | Q15: 3 | R15: 3 | S15: 6 | T15: 2 | U15: 4 | V15: 1 | W15: 1 | X15: 16 | Y15: 1 | Z15: 2 | AA15: 0 | AB15: 0 | AC15: 19 | AD15: 2 | AE15: 16 | AF15: 2 | AG15: 0 | AH15: 1 | AI15: 2 | AJ15: 348 | AK15: 348 | AL15: =AJ15-AK15 -> 0
... A38: 35 | B38: West Bengal | C38: 746 | D38: 1 | E38: 0 | F38: 8 | G38: 1 | H38: 4 | I38: 0 | J38: 368 | K38: 27 | L38: 7 | M38: 2 | N38: 0 | O38: 9 | P38: 0 | Q38: 43 | R38: 12 | S38: 24 | T38: 4 | U38: 5 | V38: 11 | W38: 15 | X38: 98 | Y38: 0 | Z38: 16 | AA38: 8 | AB38: 0 | AC38: 22 | AD38: 6 | AE38: 2 | AF38: 1 | AG38: 0 | AH38: 2 | AI38: 0 | AJ38: 1442 | AK38: 1442 | AL38: =AJ38-AK38 -> 0
A39: All India | C39: 24543 | D39: 319 | E39: 165 | F39: 739 | G39: 279 | H39: 298 | I39: 1 | J39: 4058 | K39: 3022 | L39: 85 | M39: 37 | N39: 23 | O39: 201 | P39: 7 | Q39: 768 | R39: 664 | S39: 291 | T39: 251 | U39: 195 | V39: 153 | W39: 451 | X39: 1804 | Y39: 57 | Z39: 408 | AA39: 215 | AB39: 26 | AC39: 1037 | AD39: 238 | AE39: 751 | AF39: 284 | AG39: 50 | AH39: 100 | AI39: 80 | AJ39: 41600 | AK39: 41592 | AL39: =AJ39-AK39 -> 8
AL40: =AJ40-AK40 -> 0

Sheet 5ManagementCollegeNo
A1: Table | C1: 5. Number of Private and Government Colleges (Based on Actual Response) | H1: 5(a). Enrolment in Private and Government Colleges (Based on Actual Response) | M1: 5(b). Number of Colleges Established in 2019 and their Enrolment (Based on Actual Response)
A2: Sl. No. | B2: State/UTs | C2: Private (Un-Aided) | D2: Private (Aided) | E2: Private Total | F2: Government | G2: Total | H2: =C2 -> Private (Un-Aided) | I2: =D2 -> Private (Aided) | J2: Private Total | K2: Government | L2: Total | M2: =H2 -> Private (Un-Aided) | O2: =I2 -> Private (Aided) | Q2: Government | S2: Total
M3: Number | N3: Enrolment | O3: Number | P3: Enrolment | Q3: Number | R3: Enrolment | S3: Number | T3: Enrolment | U3: Gov
A4: 1 | B4: 2 | C4: 3 | D4: 4 | E4: 5 | F4: 6 | G4: 7 | H4: 3 | I4: 4 | J4: 5 | K4: 6 | L4: 7 | M4: 3 | N4: 4 | O4: 5 | P4: 6 | Q4: 7 | R4: 8 | S4: 9 | T4: 10
A5: 1 | B5: Andaman and Nicobar Islands | C5: 0 | D5: 0 | E5: 0 | F5: 9 | G5: 9 | H5: 0 | I5: 0 | J5: 0 | K5: 7608 | L5: 7608 | M5: 0 | N5: 0 | O5: 0 | P5: 0 | Q5: 0 | R5: 0 | S5: 0 | T5: 0 | U5: =K5/F5 -> 845.33333
A6: 2 | B6: Andhra Pradesh | C6: 2091 | D6: 163 | E6: 2254 | F6: 300 | G6: 2554 | H6: 1086160 | I6: 138772 | J6: 1224932 | K6: 181051 | L6: 1405983 | M6: 6 | N6: 209 | O6: 1 | P6: 40 | Q6: 2 | R6: 206 | S6: 9 | T6: 455 | U6: =K6/F6 -> 603.50333
A7: 3 | B7: Arunachal Pradesh | C7: 14 | D7: 4 | E7: 18 | F7: 23 | G7: 41 | H7: 5014 | I7: 1242 | J7: 6256 | K7: 16723 | L7: 22979 | M7: 0 | N7: 0 | O7: 0 | P7: 0 | Q7: 1 | R7: 30 | S7: 1 | T7: 30 | U7: =K7/F7 -> 727.08696
A8: 4 | B8: Assam | C8: 83 | D8: 25 | E8: 108 | F8: 452 | G8: 560 | H8: 25095 | I8: 5150 | J8: 30245 | K8: 443035 | L8: 473280 | M8: 6 | N8: 660 | O8: 2 | P8: 98 | Q8: 5 | R8: 852 | S8: 13 | T8: 1610 | U8: =K8/F8 -> 980.16593
A9: 5 | B9: Bihar | C9: 329 | D9: 158 | E9: 487 | F9: 545 | G9: 1032 | H9: 144505 | I9: 273361 | J9: 417866 | K9: 1528586 | L9: 1946452 | M9: 12 | N9: 2305 | O9: 3 | P9: 384 | Q9: 1 | R9: 199 | S9: 16 | T9: 2888 | U9: =K9/F9 -> 2804.745
A10: 6 | B10: Chandigarh | C10: 4 | D10: 7 | E10: 11 | F10: 15 | G10: 26 | H10: 519 | I10: 28934 | J10: 29453 | K10: 19693 | L10: 49146 | M10: 0 | N10: 0 | O10: 0 | P10: 0 | Q10: 0 | R10: 0 | S10: 0 | T10: 0 | U10: =K10/F10 -> 1312.8667
A11: 7 | B11: Chhattisgarh | C11: 368 | D11: 86 | E11: 454 | F11: 395 | G11: 849 | H11: 120268 | I11: 41175 | J11: 161443 | K11: 313252 | L11: 474695 | M11: 14 | N11: 775 | O11: 2 | P11: 53 | Q11: 5 | R11: 97 | S11: 21 | T11: 925 | U11: =K11/F11 -> 793.04304
A12: 8 | B12: Delhi | C12: 64 | D12: 11 | E12: 75 | F12: 98 | G12: 173 | H12: 61417 | I12: 19928 | J12: 81345 | K12: 200638 | L12: 281983 | M12: 0 | N12: 0 | O12: 0 | P12: 0 | Q12: 0 | R12: 0 | S12: 0 | T12: 0 | U12: =K12/F12 -> 2047.3265
A13: 9 | B13: Goa | C13: 14 | D13: 26 | E13: 40 | F13: 21 | G13: 61 | H13: 5080 | I13: 22271 | J13: 27351 | K13: 14374 | L13: 41725 | M13: 0 | N13: 0 | O13: 0 | P13: 0 | Q13: 1 | R13: 8 | S13: 1 | T13: 8 | U13: =K13/F13 -> 684.47619
A14: 10 | B14: Gujarat | C14: 1371 | D14: 474 | E14: 1845 | F14: 403 | G14: 2248 | H14: 470386 | I14: 430190 | J14: 900576 | K14: 291877 | L14: 1192453 | M14: 75 | N14: 4891 | O14: 11 | P14: 663 | Q14: 5 | R14: 312 | S14: 91 | T14: 5866 | U14: =K14/F14 -> 724.26055
A15: 11 | B15: Haryana | C15: 685 | D15: 138 | E15: 823 | F15: 258 | G15: 1081 | H15: 216786 | I15: 161322 | J15: 378108 | K15: 254673 | L15: 632781 | M15: 3 | N15: 188 | O15: 0 | P15: 0 | Q15: 14 | R15: 961 | S15: 17 | T15: 1149 | U15: =K15/F15 -> 987.10465
A16: 12 | B16: Himachal Pradesh | C16: 171 | D16: 13 | E16: 184 | F16: 164 | G16: 348 | H16: 32363 | I16: 10202 | J16: 42565 | K16: 134987 | L16: 177552 | M16: 3 | N16: 206 | O16: 0 | P16: 0 | Q16: 0 | R16: 0 | S16: 3 | T16: 206 | U16: =K16/F16 -> 823.09146
... A20: 16 | B20: Kerala | C20: 831 | D20: 225 | E20: 1056 | F20: 272 | G20: 1328 | H20: 350698 | I20: 279120 | J20: 629818 | K20: 138826 | L20: 768644 | M20: 3 | N20: 290 | O20: 1 | P20: 28 | Q20: 1 | R20: 28 | S20: 5 | T20: 346 | U20: =K20/F20 -> 510.38971
A21: 17 | B21: Ladakh | C21: 0 | D21: 0 | E21: 0 | F21: 3 | G21: 3 | H21: 0 | I21: 0 | J21: 0 | K21: 2332 | L21: 2332 | M21: 0 | N21: 0 | O21: 0 | P21: 0 | Q21: 0 | R21: 0 | U21: =K21/F21 -> 777.33333
A22: 18 | B22: Madhya Pradesh | C22: 1316 | D22: 258 | E22: 1574 | F22: 745 | G22: 2319 | H22: 553957 | I22: 146908 | J22: 700865 | K22: 1036820 | L22: 1737685 | M22: 18 | N22: 1526 | O22: 8 | P22: 483 | Q22: 6 | R22: 504 | S22: 32 | T22: 2513 | U22: =K22/F22 -> 1391.7047
A23: 19 | B23: Maharashtra | C23: 2835 | D23: 1162 | E23: 3997 | F23: 534 | G23: 4531 | H23: 1236688 | I23: 1502161 | J23: 2738849 | K23: 304486 | L23: 3043335 | M23: 76 | N23: 5718 | O23: 0 | P23: 0 | Q23: 3 | R23: 172 | S23: 79 | T23: 5890 | U23: =K23/F23 -> 570.1985
A24: 20 | B24: Manipur | C24: 28 | D24: 16 | E24: 44 | F24: 59 | G24: 103 | H24: 7246 | I24: 15601 | J24: 22847 | K24: 91560 | L24: 114407 | M24: 1 | N24: 7 | O24: 0 | P24: 0 | Q24: 0 | R24: 0 | S24: 1 | T24: 7 | U24: =K24/F24 -> 1551.8644
A25: 21 | B25: Meghalaya | C25: 17 | D25: 18 | E25: 35 | F25: 27 | G25: 62 | H25: 8535 | I25: 18207 | J25: 26742 | K25: 34535 | L25: 61277 | M25: 0 | N25: 0 | O25: 0 | P25: 0 | Q25: 0 | R25: 0 | S25: 0 | T25: 0 | U25: =K25/F25 -> 1279.0741
A26: 22 | B26: Mizoram | C26: 7 | D26: 1 | E26: 8 | F26: 31 | G26: 39 | H26: 1210 | I26: 27 | J26: 1237 | K26: 24131 | L26: 25368 | M26: 3 | N26: 228 | O26: 0 | P26: 0 | Q26: 0 | R26: 0 | S26: 3 | T26: 228 | U26: =K26/F26 -> 778.41935
A27: 23 | B27: Nagaland | C27: 12 | D27: 35 | E27: 47 | F27: 20 | G27: 67 | H27: 3743 | I27: 18472 | J27: 22215 | K27: 11081 | L27: 33296 | M27: 1 | N27: 0 | O27: 1 | P27: 20 | Q27: 0 | R27: 0 | S27: 2 | T27: 20 | U27: =K27/F27 -> 554.05
A28: 24 | B28: Odisha | C28: 382 | D28: 442 | E28: 824 | F28: 371 | G28: 1195 | H28: 151683 | I28: 284001 | J28: 435684 | K28: 255732 | L28: 691416 | M28: 40 | N28: 2435 | O28: 4 | P28: 203 | Q28: 3 | R28: 174 | S28: 47 | T28: 2812 | U28: =K28/F28 -> 689.30458
A29: 25 | B29: Puducherry | C29: 44 | D29: 1 | E29: 45 | F29: 25 | G29: 70 | H29: 23813 | I29: 84 | J29: 23897 | K29: 25566 | L29: 49463 | M29: 0 | N29: 0 | O29: 0 | P29: 0 | Q29: 0 | R29: 0 | S29: 0 | T29: 0 | U29: =K29/F29 -> 1022.64
A30: 26 | B30: Punjab | C30: 650 | D30: 181 | E30: 831 | F30: 199 | G30: 1030 | H30: 201868 | I30: 157664 | J30: 359532 | K30: 143790 | L30: 503322 | M30: 6 | N30: 425 | O30: 0 | P30: 0 | Q30: 3 | R30: 217 | S30: 9 | T30: 642 | U30: =K30/F30 -> 722.56281
A31: 27 | B31: Rajasthan | C31: 2353 | D31: 264 | E31: 2617 | F31: 722 | G31: 3339 | H31: 911656 | I31: 100101 | J31: 1011757 | K31: 712497 | L31: 1724254 | M31: 69 | N31: 6475 | O31: 16 | P31: 1080 | Q31: 54 | R31: 8527 | S31: 139 | T31: 16082 | U31: =K31/F31 -> 986.83795
A32: 28 | B32: Sikkim | C32: 4 | D32: 0 | E32: 4 | F32: 15 | G32: 19 | H32: 1124 | I32: 0 | J32: 1124 | K32: 12167 | L32: 13291 | M32: 0 | N32: 0 | O32: 0 | P32: 0 | Q32: 0 | R32: 0 | S32: 0 | T32: 0 | U32: =K32/F32 -> 811.13333
A33: 29 | B33: Tamil Nadu | C33: 2020 | D33: 265 | E33: 2285 | F33: 372 | G33: 2657 | H33: 1279814 | I33: 490400 | J33: 1770214 | K33: 465148 | L33: 2235362 | M33: 37 | N33: 2447 | O33: 9 | P33: 355 | Q33: 12 | R33: 1902 | S33: 58 | T33: 4704 | U33: =K33/F33 -> 1250.3978
... A39: 35 | B39: West Bengal | C39: 679 | D39: 271 | E39: 950 | F39: 492 | G39: 1442 | H39: 272747 | I39: 396771 | J39: 669518 | K39: 1009710 | L39: 1679228 | M39: 7 | N39: 602 | O39: 3 | P39: 295 | Q39: 1 | R39: 9 | S39: 11 | T39: 906 | U39: =K39/F39 -> 2052.2561
A40: All India | C40: 27039 | D40: 5658 | E40: 32697 | F40: 8903 | G40: 41600 | H40: 12564324 | I40: 5979206 | J40: 18543530 | K40: 9768029 | L40: 28311559 | M40: 523 | N40: 38589 | O40: 69 | P40: 4378 | Q40: 136 | R40: 15771 | S40: 728 | T40: 58738 | U40: =K40/F40 -> 1097.1615

Sheet 6TotalEnr
B1: Table | C1: 6. State-wise Estimated Enrolment at various levels | L1: 6. State-wise Estimated Enrolment at various levels | U1: 6. State-wise Estimated Enrolment at various levels
A2: Sl No | B2: State | C2: Ph.D. | F2: M.Phil. | I2: Post Graduate | L2: Under Graduate | O2: PG Diploma | R2: Diploma | U2: Certificate | X2: Integrated | AA2: Grand Total
C3: Male | D3: Female | E3: Total | F3: Male | G3: Female | H3: Total | I3: Male | J3: Female | K3: Total | L3: Male | M3: Female | N3: Total | O3: Male | P3: Female | Q3: Total | R3: Male | S3: Female | T3: Total | U3: Male | V3: Female | W3: Total | X3: Male | Y3: Female | Z3: Total | AA3: Male | AB3: Female | AC3: Total
A4: 1 | B4: 2 | C4: 3 | D4: 4 | E4: 5 | F4: 6 | G4: 7 | H4: 8 | I4: 9 | J4: 10 | K4: 11 | L4: 12 | M4: 13 | N4: 14 | O4: 15 | P4: 16 | Q4: 17 | R4: 18 | S4: 19 | T4: 20 | U4: 21 | V4: 22 | W4: 23 | X4: 24 | Y4: 25 | Z4: 26 | AA4: 27 | AB4: 28 | AC4: 29 | AD4: 30 | AE4: 31
A5: 1 | B5: Andaman and Nicobar Islands | C5: 7 | D5: 12 | E5: 19 | F5: 0 | G5: 0 | H5: 0 | I5: 582 | J5: 979 | K5: 1561 | L5: 4055 | M5: 4672 | N5: 8727 | O5: 85 | P5: 56 | Q5: 141 | R5: 621 | S5: 455 | T5: 1076 | U5: 39 | V5: 33 | W5: 72 | X5: 145 | Y5: 224 | Z5: 369 | AA5: 5534 | AB5: 6431 | AC5: 11965 | AD5: =AC5-'9AllSAAct'!AW6 -> 11841 | AE5: 53.745819 | AF5: TRUE
A6: 2 | B6: Andhra Pradesh | C6: 4283 | D6: 2708 | E6: 6991 | F6: 70 | G6: 48 | H6: 118 | I6: 98570 | J6: 97244 | K6: 195814 | L6: 846588 | M6: 759307 | N6: 1605895 | O6: 758 | P6: 431 | Q6: 1189 | R6: 96913 | S6: 66591 | T6: 163504 | U6: 454 | V6: 696 | W6: 1150 | X6: 8429 | Y6: 4528 | Z6: 12957 | AA6: 1056065 | AB6: 931553 | AC6: 1987618 | AD6: =AC6-'9AllSAAct'!AW7 -> 1869290 | AE6: 46.832408 | AF6: TRUE
A7: 3 | B7: Arunachal Pradesh | C7: 470 | D7: 258 | E7: 728 | F7: 56 | G7: 74 | H7: 130 | I7: 5623 | J7: 5814 | K7: 11437 | L7: 22310 | M7: 20017 | N7: 42327 | O7: 97 | P7: 80 | Q7: 177 | R7: 1403 | S7: 1139 | T7: 2542 | U7: 310 | V7: 162 | W7: 472 | X7: 1196 | Y7: 726 | Z7: 1922 | AA7: 31465 | AB7: 28270 | AC7: 59735 | AD7: =AC7-'9AllSAAct'!AW8 -> 58721 | AE7: 47.257986 | AF7: TRUE
A8: 4 | B8: Assam | C8: 3648 | D8: 2356 | E8: 6004 | F8: 126 | G8: 180 | H8: 306 | I8: 23461 | J8: 33328 | K8: 56789 | L8: 297876 | M8: 304835 | N8: 602711 | O8: 984 | P8: 946 | Q8: 1930 | R8: 12972 | S8: 9814 | T8: 22786 | U8: 459 | V8: 866 | W8: 1325 | X8: 2459 | Y8: 2783 | Z8: 5242 | AA8: 341985 | AB8: 355108 | AC8: 697093 | AD8: =AC8-'9AllSAAct'!AW9 -> 679640 | AE8: 50.923616 | AF8: TRUE
A9: 5 | B9: Bihar | C9: 2625 | D9: 1183 | E9: 3808 | F9: 50 | G9: 23 | H9: 73 | I9: 99157 | J9: 84462 | K9: 183619 | L9: 1141620 | M9: 911387 | N9: 2053007 | O9: 2798 | P9: 1077 | Q9: 3875 | R9: 57296 | S9: 49189 | T9: 106485 | U9: 3264 | V9: 2885 | W9: 6149 | X9: 2592 | Y9: 1333 | Z9: 3925 | AA9: 1309402 | AB9: 1051539 | AC9: 2360941 | AD9: =AC9-'9AllSAAct'!AW10 -> 2290638 | AE9: 44.923324 | AF9: TRUE
A10: 6 | B10: Chandigarh | C10: 323 | D10: 427 | E10: 750 | F10: 158 | G10: 29 | H10: 187 | I10: 8669 | J10: 13715 | K10: 22384 | L10: 40358 | M10: 35349 | N10: 75707 | O10: 1138 | P10: 1181 | Q10: 2319 | R10: 3035 | S10: 3631 | T10: 6666 | U10: 245 | V10: 237 | W10: 482 | X10: 883 | Y10: 1087 | Z10: 1970 | AA10: 54809 | AB10: 55656 | AC10: 110465 | AD10: =AC10-'9AllSAAct'!AW11 -> 106735 | AE10: 50.176752 | AF10: TRUE
A11: 7 | B11: Chhattisgarh | C11: 910 | D11: 744 | E11: 1654 | F11: 36 | G11: 22 | H11: 58 | I11: 33737 | J11: 46771 | K11: 80508 | L11: 215732 | M11: 259411 | N11: 475143 | O11: 14443 | P11: 14621 | Q11: 29064 | R11: 36144 | S11: 27021 | T11: 63165 | U11: 296 | V11: 435 | W11: 731 | X11: 1542 | Y11: 1540 | Z11: 3082 | AA11: 302840 | AB11: 350565 | AC11: 653405 | AD11: =AC11-'9AllSAAct'!AW12 -> 646847 | AE11: 53.468729 | AF11: TRUE
A12: 8 | B12: Delhi | C12: 8112 | D12: 7332 | E12: 15444 | F12: 772 | G12: 764 | H12: 1536 | I12: 69649 | J12: 97222 | K12: 166871 | L12: 454449 | M12: 409832 | N12: 864281 | O12: 9715 | P12: 7442 | Q12: 17157 | R12: 17002 | S12: 15459 | T12: 32461 | U12: 1415 | V12: 1143 | W12: 2558 | X12: 3735 | Y12: 2228 | Z12: 5963 | AA12: 564849 | AB12: 541422 | AC12: 1106271 | AD12: =AC12-'9AllSAAct'!AW13 -> 1081454 | AE12: 48.932658 | AF12: TRUE
A13: 9 | B13: Goa | C13: 276 | D13: 340 | E13: 616 | F13: 6 | G13: 2 | H13: 8 | I13: 3113 | J13: 4464 | K13: 7577 | L13: 20785 | M13: 23406 | N13: 44191 | O13: 108 | P13: 139 | Q13: 247 | R13: 4677 | S13: 1593 | T13: 6270 | U13: 17 | V13: 14 | W13: 31 | X13: 422 | Y13: 923 | Z13: 1345 | AA13: 29404 | AB13: 30881 | AC13: 60285 | AD13: =AC13-'9AllSAAct'!AW14 -> 52433 | AE13: 51.354314 | AF13: TRUE
A14: 10 | B14: Gujarat | C14: 4819 | D14: 3202 | E14: 8021 | F14: 135 | G14: 177 | H14: 312 | I14: 86719 | J14: 99388 | K14: 186107 | L14: 712608 | M14: 545854 | N14: 1258462 | O14: 3856 | P14: 3072 | Q14: 6928 | R14: 103346 | S14: 50683 | T14: 154029 | U14: 17256 | V14: 5035 | W14: 22291 | X14: 9405 | Y14: 7575 | Z14: 16980 | AA14: 938144 | AB14: 714986 | AC14: 1653130 | AD14: =AC14-'9AllSAAct'!AW15 -> 1623232 | AE14: 43.084877 | AF14: TRUE
A15: 11 | B15: Haryana | C15: 2046 | D15: 2502 | E15: 4548 | F15: 104 | G15: 142 | H15: 246 | I15: 50192 | J15: 80377 | K15: 130569 | L15: 392179 | M15: 389514 | N15: 781693 | O15: 1596 | P15: 1331 | Q15: 2927 | R15: 61163 | S15: 28798 | T15: 89961 | U15: 693 | V15: 991 | W15: 1684 | X15: 9840 | Y15: 7691 | Z15: 17531 | AA15: 517813 | AB15: 511346 | AC15: 1029159 | AD15: =AC15-'9AllSAAct'!AW16 -> 968625 | AE15: 49.614327 | AF15: TRUE
A16: 12 | B16: Himachal Pradesh | C16: 1100 | D16: 1012 | E16: 2112 | F16: 136 | G16: 134 | H16: 270 | I16: 13471 | J16: 16133 | K16: 29604 | L16: 107717 | M16: 128469 | N16: 236186 | O16: 730 | P16: 753 | Q16: 1483 | R16: 8214 | S16: 8687 | T16: 16901 | U16: 324 | V16: 236 | W16: 560 | X16: 1504 | Y16: 965 | Z16: 2469 | AA16: 133196 | AB16: 156389 | AC16: 289585 | AD16: =AC16-'9AllSAAct'!AW17 -> 277261 | AE16: 53.914706 | AF16: TRUE
... A20: 16 | B20: Kerala | C20: 3184 | D20: 5554 | E20: 8738 | F20: 207 | G20: 745 | H20: 952 | I20: 45876 | J20: 120643 | K20: 166519 | L20: 454250 | M20: 633728 | N20: 1087978 | O20: 1498 | P20: 1621 | Q20: 3119 | R20: 49106 | S20: 33686 | T20: 82792 | U20: 1278 | V20: 3429 | W20: 4707 | X20: 4226 | Y20: 5505 | Z20: 9731 | AA20: 559625 | AB20: 804911 | AC20: 1364536 | AD20: =AC20-'9AllSAAct'!AW21 -> 1289207 | AE20: 58.885068 | AF20: TRUE
A21: 17 | B21: Ladakh | C21: 6 | D21: 2 | E21: 8 | F21: 0 | G21: 0 | H21: 0 | I21: 70 | J21: 23 | K21: 93 | L21: 740 | M21: 1738 | N21: 2478 | O21: 0 | P21: 0 | Q21: 0 | R21: 245 | S21: 185 | T21: 430 | U21: 0 | V21: 0 | W21: 0 | X21: 47 | Y21: 91 | Z21: 138 | AA21: 1108 | AB21: 2039 | AC21: 3147 | AD21: =AC21-'9AllSAAct'!AW22 -> 2932
A22: 18 | B22: Lakshadweep | C22: 0 | D22: 0 | E22: 0 | F22: 0 | G22: 0 | H22: 0 | I22: 0 | J22: 26 | K22: 26 | L22: 133 | M22: 401 | N22: 534 | O22: 0 | P22: 0 | Q22: 0 | R22: 0 | S22: 0 | T22: 0 | U22: 0 | V22: 0 | W22: 0 | X22: 0 | Y22: 0 | Z22: 0 | AA22: 133 | AB22: 427 | AC22: 560 | AD22: =AC22-'9AllSAAct'!AW23 -> 560 | AF22: FALSE
A23: 19 | B23: Madhya Pradesh | C23: 3676 | D23: 2477 | E23: 6153 | F23: 91 | G23: 58 | H23: 149 | I23: 159236 | J23: 184377 | K23: 343613 | L23: 1067537 | M23: 947070 | N23: 2014607 | O23: 21531 | P23: 19739 | Q23: 41270 | R23: 103265 | S23: 56449 | T23: 159714 | U23: 2298 | V23: 1272 | W23: 3570 | X23: 16402 | Y23: 13083 | Z23: 29485 | AA23: 1374036 | AB23: 1224525 | AC23: 2598561 | AD23: =AC23-'9AllSAAct'!AW24 -> 2542272 | AE23: 47.170897 | AF23: FALSE | AG23: 0
A24: 20 | B24: Maharashtra | C24: 9358 | D24: 6393 | E24: 15751 | F24: 385 | G24: 349 | H24: 734 | I24: 244931 | J24: 319628 | K24: 564559 | L24: 1955828 | M24: 1538148 | N24: 3493976 | O24: 14155 | P24: 10540 | Q24: 24695 | R24: 236423 | S24: 157788 | T24: 394211 | U24: 22503 | V24: 13879 | W24: 36382 | X24: 8314 | Y24: 7527 | Z24: 15841 | AA24: 2491897 | AB24: 2054252 | AC24: 4546149 | AD24: =AC24-'9AllSAAct'!AW25 -> 4220474 | AE24: 45.074784 | AF24: FALSE | AG24: 0
A25: 21 | B25: Manipur | C25: 624 | D25: 569 | E25: 1193 | F25: 0 | G25: 12 | H25: 12 | I25: 4813 | J25: 5649 | K25: 10462 | L25: 61246 | M25: 60261 | N25: 121507 | O25: 396 | P25: 269 | Q25: 665 | R25: 1637 | S25: 2607 | T25: 4244 | U25: 200 | V25: 216 | W25: 416 | X25: 0 | Y25: 0 | Z25: 0 | AA25: 68916 | AB25: 69583 | AC25: 138499 | AD25: =AC25-'9AllSAAct'!AW26 -> 135361 | AE25: 50.024748 | AF25: FALSE
A26: 22 | B26: Meghalaya | C26: 469 | D26: 364 | E26: 833 | F26: 0 | G26: 0 | H26: 0 | I26: 4039 | J26: 6124 | K26: 10163 | L26: 36840 | M26: 45359 | N26: 82199 | O26: 177 | P26: 129 | Q26: 306 | R26: 1334 | S26: 2236 | T26: 3570 | U26: 172 | V26: 214 | W26: 386 | X26: 73 | Y26: 54 | Z26: 127 | AA26: 43104 | AB26: 54480 | AC26: 97584 | AD26: =AC26-'9AllSAAct'!AW27 -> 93390 | AE26: 55.413124 | AF26: FALSE
A27: 23 | B27: Mizoram | C27: 551 | D27: 436 | E27: 987 | F27: 56 | G27: 59 | H27: 115 | I27: 1992 | J27: 2478 | K27: 4470 | L27: 15802 | M27: 14971 | N27: 30773 | O27: 61 | P27: 42 | Q27: 103 | R27: 710 | S27: 1480 | T27: 2190 | U27: 0 | V27: 20 | W27: 20 | X27: 29 | Y27: 23 | Z27: 52 | AA27: 19201 | AB27: 19509 | AC27: 38710 | AD27: =AC27-'9AllSAAct'!AW28 -> 36298 | AE27: 50.39783 | AF27: FALSE
A28: 24 | B28: Nagaland | C28: 279 | D28: 314 | E28: 593 | F28: 23 | G28: 30 | H28: 53 | I28: 2843 | J28: 4252 | K28: 7095 | L28: 17600 | M28: 19228 | N28: 36828 | O28: 42 | P28: 71 | Q28: 113 | R28: 859 | S28: 1210 | T28: 2069 | U28: 98 | V28: 99 | W28: 197 | X28: 6 | Y28: 0 | Z28: 6 | AA28: 21750 | AB28: 25204 | AC28: 46954 | AD28: =AC28-'9AllSAAct'!AW29 -> 45140 | AE28: 53.654843 | AF28: FALSE
A29: 25 | B29: Odisha | C29: 1955 | D29: 1326 | E29: 3281 | F29: 352 | G29: 378 | H29: 730 | I29: 48874 | J29: 50344 | K29: 99218 | L29: 370312 | M29: 368176 | N29: 738488 | O29: 2408 | P29: 1394 | Q29: 3802 | R29: 94732 | S29: 50884 | T29: 145616 | U29: 1321 | V29: 2268 | W29: 3589 | X29: 5929 | Y29: 6369 | Z29: 12298 | AA29: 525883 | AB29: 481139 | AC29: 1007022 | AD29: =AC29-'9AllSAAct'!AW30 -> 879153 | AE29: 47.688334 | AF29: FALSE
A30: 26 | B30: Puducherry | C30: 271 | D30: 325 | E30: 596 | F30: 0 | G30: 2 | H30: 2 | I30: 12865 | J30: 13359 | K30: 26224 | L30: 26875 | M30: 32921 | N30: 59796 | O30: 15 | P30: 16 | Q30: 31 | R30: 2806 | S30: 1056 | T30: 3862 | U30: 1 | V30: 6 | W30: 7 | X30: 354 | Y30: 381 | Z30: 735 | AA30: 43187 | AB30: 48066 | AC30: 91253 | AD30: =AC30-'9AllSAAct'!AW31 -> 87515 | AE30: 52.974037 | AF30: FALSE
A31: 27 | B31: Punjab | C31: 4628 | D31: 4938 | E31: 9566 | F31: 142 | G31: 169 | H31: 311 | I31: 43610 | J31: 60696 | K31: 104306 | L31: 302634 | M31: 284359 | N31: 586993 | O31: 1905 | P31: 2394 | Q31: 4299 | R31: 56209 | S31: 52491 | T31: 108700 | U31: 617 | V31: 696 | W31: 1313 | X31: 8499 | Y31: 9348 | Z31: 17847 | AA31: 418244 | AB31: 415091 | AC31: 833335 | AD31: =AC31-'9AllSAAct'!AW32 -> 774852 | AE31: 49.857581 | AF31: FALSE
A32: 28 | B32: Rajasthan | C32: 6588 | D32: 6379 | E32: 12967 | F32: 166 | G32: 104 | H32: 270 | I32: 113499 | J32: 134819 | K32: 248318 | L32: 1014468 | M32: 924253 | N32: 1938721 | O32: 7736 | P32: 4554 | Q32: 12290 | R32: 82769 | S32: 36538 | T32: 119307 | U32: 3930 | V32: 3916 | W32: 7846 | X32: 49148 | Y32: 43923 | Z32: 93071 | AA32: 1278304 | AB32: 1154486 | AC32: 2432790 | AD32: =AC32-'9AllSAAct'!AW33 -> 2367520 | AE32: 46.291411 | AF32: FALSE
A33: 29 | B33: Sikkim | C33: 115 | D33: 80 | E33: 195 | F33: 34 | G33: 30 | H33: 64 | I33: 2929 | J33: 4001 | K33: 6930 | L33: 12295 | M33: 12533 | N33: 24828 | O33: 32 | P33: 11 | Q33: 43 | R33: 1088 | S33: 1179 | T33: 2267 | U33: 61 | V33: 11 | W33: 72 | X33: 153 | Y33: 222 | Z33: 375 | AA33: 16707 | AB33: 18067 | AC33: 34774 | AD33: =AC33-'9AllSAAct'!AW34 -> 33164 | AE33: 51.844609 | AF33: FALSE
A34: 30 | B34: Tamil Nadu | C34: 17443 | D34: 16968 | E34: 34411 | F34: 1696 | G34: 5007 | H34: 6703 | I34: 185725 | J34: 278930 | K34: 464655 | L34: 1182067 | M34: 1280466 | N34: 2462533 | O34: 9155 | P34: 6392 | Q34: 15547 | R34: 247335 | S34: 61174 | T34: 308509 | U34: 6676 | V34: 14108 | W34: 20784 | X34: 12056 | Y34: 11241 | Z34: 23297 | AA34: 1662153 | AB34: 1674286 | AC34: 3336439 | AD34: =AC34-'9AllSAAct'!AW35 -> 3070535 | AE34: 50.137209 | AF34: FALSE
A35: 31 | B35: Telangana | C35: 4228 | D35: 2487 | E35: 6715 | F35: 106 | G35: 74 | H35: 180 | I35: 86425 | J35: 109813 | K35: 196238 | L35: 617563 | M35: 634298 | N35: 1251861 | O35: 4791 | P35: 3180 | Q35: 7971 | R35: 56054 | S35: 43630 | T35: 99684 | U35: 2276 | V35: 2203 | W35: 4479 | X35: 3866 | Y35: 2792 | Z35: 6658 | AA35: 775309 | AB35: 798477 | AC35: 1573786 | AD35: =AC35-'9AllSAAct'!AW36 -> 1484197 | AE35: 50.704529 | AF35: FALSE
A36: 32 | B36: The Dadra and Nagar Haveli and Daman and Diu | C36: 0 | D36: 0 | E36: 0 | F36: 0 | G36: 0 | H36: 0 | I36: 259 | J36: 508 | K36: 767 | L36: 4020 | M36: 4681 | N36: 8701 | O36: 0 | P36: 0 | Q36: 0 | R36: 1647 | S36: 397 | T36: 2044 | U36: 0 | V36: 0 | W36: 0 | X36: 22 | Y36: 36 | Z36: 58 | AA36: 5948 | AB36: 5622 | AC36: 11570 | AD36: =AC36-'9AllSAAct'!AW37 -> 11409
A37: 33 | B37: Tripura | C37: 452 | D37: 220 | E37: 672 | F37: 2 | G37: 10 | H37: 12 | I37: 5919 | J37: 6287 | K37: 12206 | L37: 38810 | M37: 34214 | N37: 73024 | O37: 116 | P37: 133 | Q37: 249 | R37: 2243 | S37: 2632 | T37: 4875 | U37: 15 | V37: 13 | W37: 28 | X37: 871 | Y37: 723 | Z37: 1594 | AA37: 48428 | AB37: 44232 | AC37: 92660 | AD37: =AC37-'9AllSAAct'!AW38 -> 91105 | AE37: 47.712447 | AF37: FALSE
A38: 34 | B38: Uttar Pradesh | C38: 11560 | D38: 8246 | E38: 19806 | F38: 234 | G38: 381 | H38: 615 | I38: 278090 | J38: 353448 | K38: 631538 | L38: 2820340 | M38: 2727844 | N38: 5548184 | O38: 30530 | P38: 23307 | Q38: 53837 | R38: 215020 | S38: 112030 | T38: 327050 | U38: 8672 | V38: 9459 | W38: 18131 | X38: 32566 | Y38: 19340 | Z38: 51906 | AA38: 3397012 | AB38: 3254055 | AC38: 6651067 | AD38: =AC38-'9AllSAAct'!AW39 -> 6406772 | AE38: 48.616604 | AF38: FALSE
A39: 35 | B39: Uttarakhand | C39: 4099 | D39: 2533 | E39: 6632 | F39: 4 | G39: 1 | H39: 5 | I39: 46493 | J39: 61555 | K39: 108048 | L39: 227696 | M39: 239419 | N39: 467115 | O39: 1231 | P39: 1122 | Q39: 2353 | R39: 20926 | S39: 7946 | T39: 28872 | U39: 450 | V39: 176 | W39: 626 | X39: 3951 | Y39: 2549 | Z39: 6500 | AA39: 304850 | AB39: 315301 | AC39: 620151 | AD39: =AC39-'9AllSAAct'!AW40 -> 599286 | AE39: 51.432567 | AF39: FALSE
A40: 36 | B40: West Bengal | C40: 8757 | D40: 5173 | E40: 13930 | F40: 1003 | G40: 963 | H40: 1966 | I40: 79405 | J40: 108051 | K40: 187456 | L40: 863390 | M40: 929778 | N40: 1793168 | O40: 3440 | P40: 2372 | Q40: 5812 | R40: 116868 | S40: 74479 | T40: 191347 | U40: 3381 | V40: 3119 | W40: 6500 | X40: 9939 | Y40: 5418 | Z40: 15357 | AA40: 1086183 | AB40: 1129353 | AC40: 2215536 | AD40: =AC40-'9AllSAAct'!AW41 -> 2059207 | AE40: 50.806754 | AF40: FALSE
A41: All India | C41: 116764 | D41: 95088 | E41: 211852 | F41: 6345 | G41: 10399 | H41: 16744 | I41: 2053794 | J41: 2662855 | K41: 4716649 | L41: 16747674 | M41: 15909835 | N41: 32657509 | O41: 143723 | P41: 113464 | Q41: 257187 | R41: 1873568 | S41: 1105752 | T41: 2979320 | U41: 83841 | V41: 72070 | W41: 155911 | X41: 212201 | Y41: 173340 | Z41: 385541 | AA41: 21237910 | AB41: 20142803 | AC41: 41380713 | AD41: =AC41-'9AllSAAct'!AW42 -> 39256280 | AE41: 48.521261 | AF41: FALSE
C42: 54.947745 | D42: 45.052255 | E42: 0.506822 | F42: 38.070776 | G42: 61.929224 | H42: 0.042705816 | I42: 43.794538 | J42: 56.205462 | K42: 11.681696 | L42: 51.428555 | M42: 48.571445 | N42: 78.922981 | O42: 56.150459 | P42: 43.849541 | Q42: 0.62444093 | R42: 63.747598 | S42: 36.252402 | T42: 6.9169626 | U42: 55.155035 | V42: 44.844965 | W42: 0.37435353 | X42: 55.116146 | Y42: 44.883854 | Z42: 0.93003859 | AA42: 51.478739 | AB42: 48.521261 | AC42: 100
B45: Level | C45: Female | D45: Male | E45: Enrolment | F45: Male % | G45: Female % | H45: % of Total
...

Sheet 6aTotalRegularEnr
B1: Table 6(a). | C1: State-wise Enrolment through Regular Mode at various levels | L1: State-wise Enrolment through Regular Mode at various levels | U1: State-wise Enrolment through Regular Mode at various levels
A2: Sl No | B2: State | C2: Ph.D. | F2: M.Phil. | I2: Post Graduate | L2: Under Graduate | O2: PG Diploma | R2: Diploma | U2: Certificate | X2: Integrated | AA2: Grand Total
C3: Male | D3: Female | E3: Total | F3: Male | G3: Female | H3: Total | I3: Male | J3: Female | K3: Total | L3: Male | M3: Female | N3: Total | O3: Male | P3: Female | Q3: Total | R3: Male | S3: Female | T3: Total | U3: Male | V3: Female | W3: Total | X3: Male | Y3: Female | Z3: Total | AA3: Male | AB3: Female | AC3: Total
A4: 1 | B4: 2 | C4: 3 | D4: 4 | E4: 5 | F4: 6 | G4: 7 | H4: 8 | I4: 9 | J4: 10 | K4: 11 | L4: 12 | M4: 13 | N4: 14 | O4: 15 | P4: 16 | Q4: 17 | R4: 18 | S4: 19 | T4: 20 | U4: 21 | V4: 22 | W4: 23 | X4: 24 | Y4: 25 | Z4: 26 | AA4: 27 | AB4: 28 | AC4: 29 | AD4: DistanceEnrolment
